Traceback (most recent call last):
  File "/Users/runner/hostedtoolcache/Python/3.10.11/x64/lib/python3.10/site-packages/jupyter_cache/executors/utils.py", line 58, in single_nb_execution
    executenb(
  File "/Users/runner/hostedtoolcache/Python/3.10.11/x64/lib/python3.10/site-packages/nbclient/client.py", line 1305, in execute
    return NotebookClient(nb=nb, resources=resources, km=km, **kwargs).execute()
  File "/Users/runner/hostedtoolcache/Python/3.10.11/x64/lib/python3.10/site-packages/jupyter_core/utils/__init__.py", line 166, in wrapped
    return loop.run_until_complete(inner)
  File "/Users/runner/hostedtoolcache/Python/3.10.11/x64/lib/python3.10/asyncio/base_events.py", line 649, in run_until_complete
    return future.result()
  File "/Users/runner/hostedtoolcache/Python/3.10.11/x64/lib/python3.10/site-packages/nbclient/client.py", line 705, in async_execute
    await self.async_execute_cell(
  File "/Users/runner/hostedtoolcache/Python/3.10.11/x64/lib/python3.10/site-packages/nbclient/client.py", line 1058, in async_execute_cell
    await self._check_raise_for_error(cell, cell_index, exec_reply)
  File "/Users/runner/hostedtoolcache/Python/3.10.11/x64/lib/python3.10/site-packages/nbclient/client.py", line 914, in _check_raise_for_error
    raise CellExecutionError.from_cell_and_msg(cell, exec_reply_content)
nbclient.exceptions.CellExecutionError: An error occurred while executing the following cell:
------------------
res_0.compare_lm_test(res_1)
------------------


[0;31m---------------------------------------------------------------------------[0m
[0;31mValueError[0m                                Traceback (most recent call last)
Cell [0;32mIn[43], line 1[0m
[0;32m----> 1[0m [43mres_0[49m[38;5;241;43m.[39;49m[43mcompare_lm_test[49m[43m([49m[43mres_1[49m[43m)[49m

File [0;32m~/hostedtoolcache/Python/3.10.11/x64/lib/python3.10/site-packages/statsmodels/regression/linear_model.py:2192[0m, in [0;36mRegressionResults.compare_lm_test[0;34m(self, restricted, demean, use_lr)[0m
[1;32m   2190[0m wresid [38;5;241m=[39m restricted[38;5;241m.[39mwresid
[1;32m   2191[0m wexog [38;5;241m=[39m [38;5;28mself[39m[38;5;241m.[39mmodel[38;5;241m.[39mwexog
[0;32m-> 2192[0m scores [38;5;241m=[39m wexog [38;5;241m*[39m [43mwresid[49m[43m[[49m[43m:[49m[43m,[49m[43m [49m[38;5;28;43;01mNone[39;49;00m[43m][49m
[1;32m   2194[0m n [38;5;241m=[39m [38;5;28mself[39m[38;5;241m.[39mnobs
[1;32m   2195[0m df_full [38;5;241m=[39m [38;5;28mself[39m[38;5;241m.[39mdf_resid

File [0;32m~/hostedtoolcache/Python/3.10.11/x64/lib/python3.10/site-packages/pandas/core/series.py:1033[0m, in [0;36mSeries.__getitem__[0;34m(self, key)[0m
[1;32m   1030[0m     key [38;5;241m=[39m np[38;5;241m.[39masarray(key, dtype[38;5;241m=[39m[38;5;28mbool[39m)
[1;32m   1031[0m     [38;5;28;01mreturn[39;00m [38;5;28mself[39m[38;5;241m.[39m_get_values(key)
[0;32m-> 1033[0m [38;5;28;01mreturn[39;00m [38;5;28;43mself[39;49m[38;5;241;43m.[39;49m[43m_get_with[49m[43m([49m[43mkey[49m[43m)[49m

File [0;32m~/hostedtoolcache/Python/3.10.11/x64/lib/python3.10/site-packages/pandas/core/series.py:1048[0m, in [0;36mSeries._get_with[0;34m(self, key)[0m
[1;32m   1043[0m     [38;5;28;01mraise[39;00m [38;5;167;01mTypeError[39;00m(
[1;32m   1044[0m         [38;5;124m"[39m[38;5;124mIndexing a Series with DataFrame is not [39m[38;5;124m"[39m
[1;32m   1045[0m         [38;5;124m"[39m[38;5;124msupported, use the appropriate DataFrame column[39m[38;5;124m"[39m
[1;32m   1046[0m     )
[1;32m   1047[0m [38;5;28;01melif[39;00m [38;5;28misinstance[39m(key, [38;5;28mtuple[39m):
[0;32m-> 1048[0m     [38;5;28;01mreturn[39;00m [38;5;28;43mself[39;49m[38;5;241;43m.[39;49m[43m_get_values_tuple[49m[43m([49m[43mkey[49m[43m)[49m
[1;32m   1050[0m [38;5;28;01melif[39;00m [38;5;129;01mnot[39;00m is_list_like(key):
[1;32m   1051[0m     [38;5;66;03m# e.g. scalars that aren't recognized by lib.is_scalar, GH#32684[39;00m
[1;32m   1052[0m     [38;5;28;01mreturn[39;00m [38;5;28mself[39m[38;5;241m.[39mloc[key]

File [0;32m~/hostedtoolcache/Python/3.10.11/x64/lib/python3.10/site-packages/pandas/core/series.py:1082[0m, in [0;36mSeries._get_values_tuple[0;34m(self, key)[0m
[1;32m   1077[0m [38;5;28;01mif[39;00m com[38;5;241m.[39many_none([38;5;241m*[39mkey):
[1;32m   1078[0m     [38;5;66;03m# mpl compat if we look up e.g. ser[:, np.newaxis];[39;00m
[1;32m   1079[0m     [38;5;66;03m#  see tests.series.timeseries.test_mpl_compat_hack[39;00m
[1;32m   1080[0m     [38;5;66;03m# the asarray is needed to avoid returning a 2D DatetimeArray[39;00m
[1;32m   1081[0m     result [38;5;241m=[39m np[38;5;241m.[39masarray([38;5;28mself[39m[38;5;241m.[39m_values[key])
[0;32m-> 1082[0m     [43mdisallow_ndim_indexing[49m[43m([49m[43mresult[49m[43m)[49m
[1;32m   1083[0m     [38;5;28;01mreturn[39;00m result
[1;32m   1085[0m [38;5;28;01mif[39;00m [38;5;129;01mnot[39;00m [38;5;28misinstance[39m([38;5;28mself[39m[38;5;241m.[39mindex, MultiIndex):

File [0;32m~/hostedtoolcache/Python/3.10.11/x64/lib/python3.10/site-packages/pandas/core/indexers/utils.py:343[0m, in [0;36mdisallow_ndim_indexing[0;34m(result)[0m
[1;32m    335[0m [38;5;250m[39m[38;5;124;03m"""[39;00m
[1;32m    336[0m [38;5;124;03mHelper function to disallow multi-dimensional indexing on 1D Series/Index.[39;00m
[1;32m    337[0m 
[0;32m   (...)[0m
[1;32m    340[0m [38;5;124;03min GH#30588.[39;00m
[1;32m    341[0m [38;5;124;03m"""[39;00m
[1;32m    342[0m [38;5;28;01mif[39;00m np[38;5;241m.[39mndim(result) [38;5;241m>[39m [38;5;241m1[39m:
[0;32m--> 343[0m     [38;5;28;01mraise[39;00m [38;5;167;01mValueError[39;00m(
[1;32m    344[0m         [38;5;124m"[39m[38;5;124mMulti-dimensional indexing (e.g. `obj[:, None]`) is no longer [39m[38;5;124m"[39m
[1;32m    345[0m         [38;5;124m"[39m[38;5;124msupported. Convert to a numpy array before indexing instead.[39m[38;5;124m"[39m
[1;32m    346[0m     )

[0;31mValueError[0m: Multi-dimensional indexing (e.g. `obj[:, None]`) is no longer supported. Convert to a numpy array before indexing instead.

