Traceback (most recent call last):
  File "/Users/runner/hostedtoolcache/Python/3.10.13/x64/lib/python3.10/site-packages/jupyter_cache/executors/utils.py", line 58, in single_nb_execution
    executenb(
  File "/Users/runner/hostedtoolcache/Python/3.10.13/x64/lib/python3.10/site-packages/nbclient/client.py", line 1305, in execute
    return NotebookClient(nb=nb, resources=resources, km=km, **kwargs).execute()
  File "/Users/runner/hostedtoolcache/Python/3.10.13/x64/lib/python3.10/site-packages/jupyter_core/utils/__init__.py", line 165, in wrapped
    return loop.run_until_complete(inner)
  File "/Users/runner/hostedtoolcache/Python/3.10.13/x64/lib/python3.10/asyncio/base_events.py", line 649, in run_until_complete
    return future.result()
  File "/Users/runner/hostedtoolcache/Python/3.10.13/x64/lib/python3.10/site-packages/nbclient/client.py", line 705, in async_execute
    await self.async_execute_cell(
  File "/Users/runner/hostedtoolcache/Python/3.10.13/x64/lib/python3.10/site-packages/nbclient/client.py", line 1058, in async_execute_cell
    await self._check_raise_for_error(cell, cell_index, exec_reply)
  File "/Users/runner/hostedtoolcache/Python/3.10.13/x64/lib/python3.10/site-packages/nbclient/client.py", line 914, in _check_raise_for_error
    raise CellExecutionError.from_cell_and_msg(cell, exec_reply_content)
nbclient.exceptions.CellExecutionError: An error occurred while executing the following cell:
------------------
import matplotlib.pyplot as plt
import numpy as np
import pandas as pd
import py4macro
import wooldridge

from py4etrics.hetero_test import *
from scipy.stats import logistic, norm, chi2
from statsmodels.formula.api import ols, logit, probit

# 警告メッセージを非表示
import warnings
warnings.filterwarnings("ignore")
------------------


[0;31m---------------------------------------------------------------------------[0m
[0;31mModuleNotFoundError[0m                       Traceback (most recent call last)
Cell [0;32mIn[1], line 4[0m
[1;32m      2[0m [38;5;28;01mimport[39;00m [38;5;21;01mnumpy[39;00m [38;5;28;01mas[39;00m [38;5;21;01mnp[39;00m
[1;32m      3[0m [38;5;28;01mimport[39;00m [38;5;21;01mpandas[39;00m [38;5;28;01mas[39;00m [38;5;21;01mpd[39;00m
[0;32m----> 4[0m [38;5;28;01mimport[39;00m [38;5;21;01mpy4macro[39;00m
[1;32m      5[0m [38;5;28;01mimport[39;00m [38;5;21;01mwooldridge[39;00m
[1;32m      7[0m [38;5;28;01mfrom[39;00m [38;5;21;01mpy4etrics[39;00m[38;5;21;01m.[39;00m[38;5;21;01mhetero_test[39;00m [38;5;28;01mimport[39;00m [38;5;241m*[39m

[0;31mModuleNotFoundError[0m: No module named 'py4macro'

