Traceback (most recent call last):
  File "/Users/runner/hostedtoolcache/Python/3.10.13/x64/lib/python3.10/site-packages/jupyter_cache/executors/utils.py", line 58, in single_nb_execution
    executenb(
  File "/Users/runner/hostedtoolcache/Python/3.10.13/x64/lib/python3.10/site-packages/nbclient/client.py", line 1314, in execute
    return NotebookClient(nb=nb, resources=resources, km=km, **kwargs).execute()
  File "/Users/runner/hostedtoolcache/Python/3.10.13/x64/lib/python3.10/site-packages/jupyter_core/utils/__init__.py", line 165, in wrapped
    return loop.run_until_complete(inner)
  File "/Users/runner/hostedtoolcache/Python/3.10.13/x64/lib/python3.10/asyncio/base_events.py", line 649, in run_until_complete
    return future.result()
  File "/Users/runner/hostedtoolcache/Python/3.10.13/x64/lib/python3.10/site-packages/nbclient/client.py", line 709, in async_execute
    await self.async_execute_cell(
  File "/Users/runner/hostedtoolcache/Python/3.10.13/x64/lib/python3.10/site-packages/nbclient/client.py", line 1062, in async_execute_cell
    await self._check_raise_for_error(cell, cell_index, exec_reply)
  File "/Users/runner/hostedtoolcache/Python/3.10.13/x64/lib/python3.10/site-packages/nbclient/client.py", line 918, in _check_raise_for_error
    raise CellExecutionError.from_cell_and_msg(cell, exec_reply_content)
nbclient.exceptions.CellExecutionError: An error occurred while executing the following cell:
------------------
htv = wooldridge.data('HTV')
wooldridge.data('HTV',ã€€description=True)
------------------


[0;36m  Cell [0;32mIn[7], line 2[0;36m[0m
[0;31m    wooldridge.data('HTV',ã€€description=True)[0m
[0m                          ^[0m
[0;31mSyntaxError[0m[0;31m:[0m invalid non-printable character U+3000


