Traceback (most recent call last):
  File "/Users/runner/hostedtoolcache/Python/3.8.10/x64/lib/python3.8/site-packages/jupyter_cache/executors/utils.py", line 51, in single_nb_execution
    executenb(
  File "/Users/runner/hostedtoolcache/Python/3.8.10/x64/lib/python3.8/site-packages/nbclient/client.py", line 1112, in execute
    return NotebookClient(nb=nb, resources=resources, km=km, **kwargs).execute()
  File "/Users/runner/hostedtoolcache/Python/3.8.10/x64/lib/python3.8/site-packages/nbclient/util.py", line 74, in wrapped
    return just_run(coro(*args, **kwargs))
  File "/Users/runner/hostedtoolcache/Python/3.8.10/x64/lib/python3.8/site-packages/nbclient/util.py", line 53, in just_run
    return loop.run_until_complete(coro)
  File "/Users/runner/hostedtoolcache/Python/3.8.10/x64/lib/python3.8/asyncio/base_events.py", line 616, in run_until_complete
    return future.result()
  File "/Users/runner/hostedtoolcache/Python/3.8.10/x64/lib/python3.8/site-packages/nbclient/client.py", line 553, in async_execute
    await self.async_execute_cell(
  File "/Users/runner/hostedtoolcache/Python/3.8.10/x64/lib/python3.8/site-packages/nbclient/client.py", line 857, in async_execute_cell
    self._check_raise_for_error(cell, exec_reply)
  File "/Users/runner/hostedtoolcache/Python/3.8.10/x64/lib/python3.8/site-packages/nbclient/client.py", line 760, in _check_raise_for_error
    raise CellExecutionError.from_cell_and_msg(cell, exec_reply_content)
nbclient.exceptions.CellExecutionError: An error occurred while executing the following cell:
------------------
import numpy as np
from scipy.stats import norm, uniform, gaussian_kde, multivariate_normal
import pandas as pd
from pandas.plotting import scatter_matrix
import matplotlib.pyplot as plt
from statsmodels.formula.api import ols
from statsmodels.stats.outliers_influence import variance_inflation_factor as vif
import wooldridge
from numba import njit
import seaborn as sns
from see import see
------------------

[0;31m---------------------------------------------------------------------------[0m
[0;31mModuleNotFoundError[0m                       Traceback (most recent call last)
[0;32m<ipython-input-1-ef08d4c96fd9>[0m in [0;36m<module>[0;34m[0m
[1;32m      8[0m [0;32mimport[0m [0mwooldridge[0m[0;34m[0m[0;34m[0m[0m
[1;32m      9[0m [0;32mfrom[0m [0mnumba[0m [0;32mimport[0m [0mnjit[0m[0;34m[0m[0;34m[0m[0m
[0;32m---> 10[0;31m [0;32mimport[0m [0mseaborn[0m [0;32mas[0m [0msns[0m[0;34m[0m[0;34m[0m[0m
[0m[1;32m     11[0m [0;32mfrom[0m [0msee[0m [0;32mimport[0m [0msee[0m[0;34m[0m[0;34m[0m[0m

[0;31mModuleNotFoundError[0m: No module named 'seaborn'
ModuleNotFoundError: No module named 'seaborn'

