Traceback (most recent call last):
  File "/Users/runner/hostedtoolcache/Python/3.10.13/x64/lib/python3.10/site-packages/jupyter_cache/executors/utils.py", line 58, in single_nb_execution
    executenb(
  File "/Users/runner/hostedtoolcache/Python/3.10.13/x64/lib/python3.10/site-packages/nbclient/client.py", line 1305, in execute
    return NotebookClient(nb=nb, resources=resources, km=km, **kwargs).execute()
  File "/Users/runner/hostedtoolcache/Python/3.10.13/x64/lib/python3.10/site-packages/jupyter_core/utils/__init__.py", line 165, in wrapped
    return loop.run_until_complete(inner)
  File "/Users/runner/hostedtoolcache/Python/3.10.13/x64/lib/python3.10/asyncio/base_events.py", line 649, in run_until_complete
    return future.result()
  File "/Users/runner/hostedtoolcache/Python/3.10.13/x64/lib/python3.10/site-packages/nbclient/client.py", line 705, in async_execute
    await self.async_execute_cell(
  File "/Users/runner/hostedtoolcache/Python/3.10.13/x64/lib/python3.10/site-packages/nbclient/client.py", line 1058, in async_execute_cell
    await self._check_raise_for_error(cell, cell_index, exec_reply)
  File "/Users/runner/hostedtoolcache/Python/3.10.13/x64/lib/python3.10/site-packages/nbclient/client.py", line 914, in _check_raise_for_error
    raise CellExecutionError.from_cell_and_msg(cell, exec_reply_content)
nbclient.exceptions.CellExecutionError: An error occurred while executing the following cell:
------------------
import gapminder, linearmodels, lmdiag, matplotlib, numba, numpy, pandas, py4macro, py4etrics, scipy, statsmodels, wooldridge
from platform import python_version

packages = ['Python','gapminder','linearmodels', 'lmdiag','matplotlib', 'numba', 'numpy','pandas', 'py4macro', 'py4etrics', 'scipy', 'statsmodels', 'wooldridge']
versions = [python_version(),gapminder.__version__, linearmodels.__version__, '0.3.7', matplotlib.__version__, numba.__version__, numpy.__version__, pandas.__version__, py4macro.__version__, py4etrics.__version__, scipy.__version__, statsmodels.__version__, wooldridge.__version__]

for pack, ver in zip(packages, versions):
    print('{0:14}{1}'.format(pack,ver))
------------------


[0;31m---------------------------------------------------------------------------[0m
[0;31mModuleNotFoundError[0m                       Traceback (most recent call last)
Cell [0;32mIn[1], line 1[0m
[0;32m----> 1[0m [38;5;28;01mimport[39;00m [38;5;21;01mgapminder[39;00m[38;5;241m,[39m [38;5;21;01mlinearmodels[39;00m[38;5;241m,[39m [38;5;21;01mlmdiag[39;00m[38;5;241m,[39m [38;5;21;01mmatplotlib[39;00m[38;5;241m,[39m [38;5;21;01mnumba[39;00m[38;5;241m,[39m [38;5;21;01mnumpy[39;00m[38;5;241m,[39m [38;5;21;01mpandas[39;00m[38;5;241m,[39m [38;5;21;01mpy4macro[39;00m[38;5;241m,[39m [38;5;21;01mpy4etrics[39;00m[38;5;241m,[39m [38;5;21;01mscipy[39;00m[38;5;241m,[39m [38;5;21;01mstatsmodels[39;00m[38;5;241m,[39m [38;5;21;01mwooldridge[39;00m
[1;32m      2[0m [38;5;28;01mfrom[39;00m [38;5;21;01mplatform[39;00m [38;5;28;01mimport[39;00m python_version
[1;32m      4[0m packages [38;5;241m=[39m [[38;5;124m'[39m[38;5;124mPython[39m[38;5;124m'[39m,[38;5;124m'[39m[38;5;124mgapminder[39m[38;5;124m'[39m,[38;5;124m'[39m[38;5;124mlinearmodels[39m[38;5;124m'[39m, [38;5;124m'[39m[38;5;124mlmdiag[39m[38;5;124m'[39m,[38;5;124m'[39m[38;5;124mmatplotlib[39m[38;5;124m'[39m, [38;5;124m'[39m[38;5;124mnumba[39m[38;5;124m'[39m, [38;5;124m'[39m[38;5;124mnumpy[39m[38;5;124m'[39m,[38;5;124m'[39m[38;5;124mpandas[39m[38;5;124m'[39m, [38;5;124m'[39m[38;5;124mpy4macro[39m[38;5;124m'[39m, [38;5;124m'[39m[38;5;124mpy4etrics[39m[38;5;124m'[39m, [38;5;124m'[39m[38;5;124mscipy[39m[38;5;124m'[39m, [38;5;124m'[39m[38;5;124mstatsmodels[39m[38;5;124m'[39m, [38;5;124m'[39m[38;5;124mwooldridge[39m[38;5;124m'[39m]

[0;31mModuleNotFoundError[0m: No module named 'py4macro'

